<?xml version="1.0" encoding="utf-8"?>
<!-- This URDF was automatically created by SolidWorks to URDF Exporter! Originally created by Stephen Brawner (brawner@gmail.com) 
     Commit Version: 1.6.0-4-g7f85cfe  Build Version: 1.6.7995.38578
     For more information, please see http://wiki.ros.org/sw_urdf_exporter -->
<robot
  name="BalanceBotMini.SLDASM">
  <link
    name="base_link">
    <inertial>
      <origin
        xyz="0.00061042 0.043299 -4.9756E-06"
        rpy="0 0 0" />
      <mass
        value="0.099831" />
      <inertia
        ixx="7.7865E-05"
        ixy="-3.4235E-19"
        ixz="1.6802E-10"
        iyy="4.1903E-05"
        iyz="-6.1212E-20"
        izz="5.6241E-05" />
    </inertial>
    <visual>
      <origin
        xyz="0 0 0"
        rpy="0 0 0" />
      <geometry>
        <mesh
          filename="package://BalanceBotMini.SLDASM/meshes/base_link.STL" />
      </geometry>
      <material
        name="">
        <color
          rgba="0.79216 0.81961 0.93333 1" />
      </material>
    </visual>
    <collision>
      <origin
        xyz="0 0 0"
        rpy="0 0 0" />
      <geometry>
        <mesh
          filename="package://BalanceBotMini.SLDASM/meshes/base_link.STL" />
      </geometry>
    </collision>
  </link>
  <link
    name="right_wheel">
    <inertial>
      <origin
        xyz="2.545E-17 1.5613E-17 -0.0857"
        rpy="0 0 0" />
      <mass
        value="0.0043782" />
      <inertia
        ixx="7.8378E-07"
        ixy="-2.6595E-22"
        ixz="4.9414E-23"
        iyy="7.8378E-07"
        iyz="-1.05E-22"
        izz="1.5559E-06" />
    </inertial>
    <visual>
      <origin
        xyz="0 0 0"
        rpy="0 0 0" />
      <geometry>
        <mesh
          filename="package://BalanceBotMini.SLDASM/meshes/right_wheel.STL" />
      </geometry>
      <material
        name="">
        <color
          rgba="0.79216 0.81961 0.93333 1" />
      </material>
    </visual>
    <collision>
      <origin
        xyz="0 0 0"
        rpy="0 0 0" />
      <geometry>
        <mesh
          filename="package://BalanceBotMini.SLDASM/meshes/right_wheel.STL" />
      </geometry>
    </collision>
  </link>
  <joint
    name="right_servo"
    type="continuous">
    <origin
      xyz="0 0.0095 0.0387"
      rpy="0 0 0" />
    <parent
      link="base_link" />
    <child
      link="right_wheel" />
    <axis
      xyz="0 0 -1" />
    <limit
      effort="0.52"
      velocity="10.89" />
  </joint>
  <link
    name="left_wheel">
    <inertial>
      <origin
        xyz="0 0 0"
        rpy="0 0 0" />
      <mass
        value="0" />
      <inertia
        ixx="0"
        ixy="0"
        ixz="0"
        iyy="0"
        iyz="0"
        izz="0" />
    </inertial>
    <visual>
      <origin
        xyz="0 0 0"
        rpy="0 0 0" />
      <geometry>
        <mesh
          filename="package://BalanceBotMini.SLDASM/meshes/left_wheel.STL" />
      </geometry>
      <material
        name="">
        <color
          rgba="1 1 1 1" />
      </material>
    </visual>
    <collision>
      <origin
        xyz="0 0 0"
        rpy="0 0 0" />
      <geometry>
        <mesh
          filename="package://BalanceBotMini.SLDASM/meshes/left_wheel.STL" />
      </geometry>
    </collision>
  </link>
  <joint
    name="left_servo"
    type="continuous">
    <origin
      xyz="0 0.0095 -0.0385"
      rpy="0 0 0" />
    <parent
      link="base_link" />
    <child
      link="left_wheel" />
    <axis
      xyz="0 0 -1" />
    <limit
      effort="0.52"
      velocity="10.89" />
  </joint>
</robot>